Workbook

Sheet 명세서_철거
A1: 상호 | B1: 동영종합건설㈜ | E1: (25년06월) 일용노무비 지급명세서 | V1: 기간 | W1: 45809 | AA1: 공 사 명 | AB1: 24-25년 노후공임 리모델링공사 8권역(경남) | AI1: 1
W2: 45838 | AI2: 1
A3: 번호 | B3: 성 명 | C3: 주민등 록번호 | D3: 주 소 | F3: 출 역 상 황 | V3: 총출력수 | W3: 노무비 단 가 | X3: 노 무 비 총 액 | Y3: 과세표준 | AA3: 세 액 | AE3: 차 감 지 급 액 | AF3: 영수인 | AG3: 나이 (주민번호입력시 자동산출) | AI3: 1
F4: 1 | G4: 2 | H4: 3 | I4: 4 | J4: 5 | K4: 6 | L4: 7 | M4: 8 | N4: 9 | O4: 10 | P4: 11 | Q4: 12 | R4: 13 | S4: 14 | T4: 15 | AA4: 갑근세 | AB4: 국민연금 | AC4: 고용보험 | AD4: 계 | AI4: 1
F5: 16 | G5: 17 | H5: 18 | I5: 19 | J5: 20 | K5: 21 | L5: 22 | M5: 23 | N5: 24 | O5: 25 | P5: 26 | Q5: 27 | R5: 28 | S5: 29 | T5: 30 | U5: 31 | AA5: 주민세 | AB5: 건강보험 | AC5: 장기보험 | AI5: 1 | AJ5: 연락처 | AK5: 거래은행 | AL5: 계좌번호
A6: =IF(B6>0,1,"") -> 1 | B6: 김경숙 | C6: 601021 | D6: 부산시 동래구 충렬대로410번길 56-7 | V6: =SUM(F6:U7) -> 1 | W6: 200000 | X6: =V6*W6 -> 200000 | Y6: =IF((F6*W6)>=150000,(F6*W6)-150000,0)+IF((G6*W6)>=150000,(G6*W6)-150000,0)+IF((H6*W6)>=150000,(H6*W6)-150000,0)+IF((I6*W6)>=150000,(I6*W6)-150000,0)+IF((J6*W6)>=150000,(J6*W6)-150000,0)+IF((K6*W6)>=150000,(K6*W6)-150000,0)+IF((L6*W6)>=150000,(L6*W6)-150000,0)+IF((M6*W6)>=150000,(M6*W6)-150000,0)+IF((N6*W6)>=150000,(N6*W6)-150000,0)+IF((O6*W6)>=150000,(O6*W6)-150000,0)+IF((P6*W6)>=150000,(P6*W6)-150000,0)+IF((Q6*W6)>=150000,(Q6*W6)-150000,0)+IF((R6*W6)>=150000,(R6*W6)-150000,0)+IF((S6*W6)>=150000,(S6*W6)-150000,0)+IF((T6*W6)>=150000,(T6*W6)-150000,0) -> 0 | Z6: =+Y6+Y7 -> 50000 | AA6: =IF((ROUNDDOWN((+Z6*6%)*45%,-1))>=1000,(ROUNDDOWN((+Z6*6%)*45%,-1)),0) -> 1350 | AB6: =IFERROR(IF(DATEDIF(DATE(MID(C6,1,2),MID(C6,3,2),MID(C6,5,2)),$W$2,"y")>=60,0,IF(OR(V6>=8,X6>=2200000),TRUNC(X6*4.5%,-1),0)),0) -> 0 | AC6: =IFERROR(IF(AND((DATEDIF(TEXT(LEFT(C6,6),"00-00-00"),$W$2,"Y")>19),(DATEDIF(TEXT(LEFT(C6,6),"00-00-00"),$W$2,"Y")<65)),TRUNC(X6*0.9%,-1),0),0) -> 1800 | AD6: =SUM(AA6:AC7) -> 3280 | AE6: =+X6-AD6 -> 196720 | AG6: =IF(ISERROR(DATEDIF((DATEVALUE(LEFT(C6,2)&"-"&MID(C6,3,2)&"-"&MID(C6,5,2))),$W$2,"y")),"",DATEDIF((DATEVALUE(LEFT(C6,2)&"-"&MID(C6,3,2)&"-"&MID(C6,5,2))),$W$2,"y")) -> 64 | AH6: 1 | AI6: =IF(AE6>0,1,0) -> 1 | AJ6: 010-2040-6604 | AK6: 새마을금고 | AL6: 9002-1703-0114-6
C7: -2630411 | M7: 1 | Y7: =IF((F7*W6)>=150000,(F7*W6)-150000,0)+IF((G7*W6)>=150000,(G7*W6)-150000,0)+IF((H7*W6)>=150000,(H7*W6)-150000,0)+IF((I7*W6)>=150000,(I7*W6)-150000,0)+IF((J7*W6)>=150000,(J7*W6)-150000,0)+IF((K7*W6)>=150000,(K7*W6)-150000,0)+IF((L7*W6)>=150000,(L7*W6)-150000,0)+IF((M7*W6)>=150000,(M7*W6)-150000,0)+IF((N7*W6)>=150000,(N7*W6)-150000,0)+IF((O7*W6)>=150000,(O7*W6)-150000,0)+IF((P7*W6)>=150000,(P7*W6)-150000,0)+IF((Q7*W6)>=150000,(Q7*W6)-150000,0)+IF((R7*W6)>=150000,(R7*W6)-150000,0)+IF((S7*W6)>=150000,(S7*W6)-150000,0)+IF((T7*W6)>=150000,(T7*W6)-150000,0)+IF((U7*W6)>=150000,(U7*W6)-150000,0) -> 50000 | AA7: =ROUNDDOWN(AA6*10%,-1) -> 130 | AB7: =IF(V6<8,0,(TRUNC(X6*3.545%,-1))) -> 0 | AC7: =TRUNC(((AB7*12.95%)),-1) -> 0 | AH7: 2 | AI7: =AI6 -> 1
A8: =IF(B8>0,A6+1,"") -> 2 | B8: 김숙자 | V8: =SUM(F8:U9) -> 1 | W8: 200000 | X8: =V8*W8 -> 200000 | Y8: =IF((F8*W8)>=150000,(F8*W8)-150000,0)+IF((G8*W8)>=150000,(G8*W8)-150000,0)+IF((H8*W8)>=150000,(H8*W8)-150000,0)+IF((I8*W8)>=150000,(I8*W8)-150000,0)+IF((J8*W8)>=150000,(J8*W8)-150000,0)+IF((K8*W8)>=150000,(K8*W8)-150000,0)+IF((L8*W8)>=150000,(L8*W8)-150000,0)+IF((M8*W8)>=150000,(M8*W8)-150000,0)+IF((N8*W8)>=150000,(N8*W8)-150000,0)+IF((O8*W8)>=150000,(O8*W8)-150000,0)+IF((P8*W8)>=150000,(P8*W8)-150000,0)+IF((Q8*W8)>=150000,(Q8*W8)-150000,0)+IF((R8*W8)>=150000,(R8*W8)-150000,0)+IF((S8*W8)>=150000,(S8*W8)-150000,0)+IF((T8*W8)>=150000,(T8*W8)-150000,0) -> 0 | Z8: =+Y8+Y9 -> 50000 | AA8: =IF((ROUNDDOWN((+Z8*6%)*45%,-1))>=1000,(ROUNDDOWN((+Z8*6%)*45%,-1)),0) -> 1350 | AB8: =IFERROR(IF(DATEDIF(DATE(MID(C8,1,2),MID(C8,3,2),MID(C8,5,2)),$W$2,"y")>=60,0,IF(OR(V8>=8,X8>=2200000),TRUNC(X8*4.5%,-1),0)),0) -> 0 | AC8: =IFERROR(IF(AND((DATEDIF(TEXT(LEFT(C8,6),"00-00-00"),$W$2,"Y")>19),(DATEDIF(TEXT(LEFT(C8,6),"00-00-00"),$W$2,"Y")<65)),TRUNC(X8*0.9%,-1),0),0) -> 0 | AD8: =SUM(AA8:AC9) -> 1480 | AE8: =+X8-AD8 -> 198520 | AG8: =IF(ISERROR(DATEDIF((DATEVALUE(LEFT(C8,2)&"-"&MID(C8,3,2)&"-"&MID(C8,5,2))),$W$2,"y")),"",DATEDIF((DATEVALUE(LEFT(C8,2)&"-"&MID(C8,3,2)&"-"&MID(C8,5,2))),$W$2,"y")) | AH8: 1 | AI8: =AI7 -> 1
J9: 1 | Y9: =IF((F9*W8)>=150000,(F9*W8)-150000,0)+IF((G9*W8)>=150000,(G9*W8)-150000,0)+IF((H9*W8)>=150000,(H9*W8)-150000,0)+IF((I9*W8)>=150000,(I9*W8)-150000,0)+IF((J9*W8)>=150000,(J9*W8)-150000,0)+IF((K9*W8)>=150000,(K9*W8)-150000,0)+IF((L9*W8)>=150000,(L9*W8)-150000,0)+IF((M9*W8)>=150000,(M9*W8)-150000,0)+IF((N9*W8)>=150000,(N9*W8)-150000,0)+IF((O9*W8)>=150000,(O9*W8)-150000,0)+IF((P9*W8)>=150000,(P9*W8)-150000,0)+IF((Q9*W8)>=150000,(Q9*W8)-150000,0)+IF((R9*W8)>=150000,(R9*W8)-150000,0)+IF((S9*W8)>=150000,(S9*W8)-150000,0)+IF((T9*W8)>=150000,(T9*W8)-150000,0)+IF((U9*W8)>=150000,(U9*W8)-150000,0) -> 50000 | AA9: =ROUNDDOWN(AA8*10%,-1) -> 130 | AB9: =IF(V8<8,0,(TRUNC(X8*3.545%,-1))) -> 0 | AC9: =TRUNC(((AB9*12.95%)),-1) -> 0 | AH9: 2 | AI9: =AI8 -> 1
A10: =IF(B10>0,A8+1,"") -> 3 | B10: 김진영 | V10: =SUM(F10:U11) -> 2 | W10: 200000 | X10: =V10*W10 -> 400000 | Y10: =IF((F10*W10)>=150000,(F10*W10)-150000,0)+IF((G10*W10)>=150000,(G10*W10)-150000,0)+IF((H10*W10)>=150000,(H10*W10)-150000,0)+IF((I10*W10)>=150000,(I10*W10)-150000,0)+IF((J10*W10)>=150000,(J10*W10)-150000,0)+IF((K10*W10)>=150000,(K10*W10)-150000,0)+IF((L10*W10)>=150000,(L10*W10)-150000,0)+IF((M10*W10)>=150000,(M10*W10)-150000,0)+IF((N10*W10)>=150000,(N10*W10)-150000,0)+IF((O10*W10)>=150000,(O10*W10)-150000,0)+IF((P10*W10)>=150000,(P10*W10)-150000,0)+IF((Q10*W10)>=150000,(Q10*W10)-150000,0)+IF((R10*W10)>=150000,(R10*W10)-150000,0)+IF((S10*W10)>=150000,(S10*W10)-150000,0)+IF((T10*W10)>=150000,(T10*W10)-150000,0) -> 0 | Z10: =+Y10+Y11 -> 100000 | AA10: =IF((ROUNDDOWN((+Z10*6%)*45%,-1))>=1000,(ROUNDDOWN((+Z10*6%)*45%,-1)),0) -> 2700 | AB10: =IFERROR(IF(DATEDIF(DATE(MID(C10,1,2),MID(C10,3,2),MID(C10,5,2)),$W$2,"y")>=60,0,IF(OR(V10>=8,X10>=2200000),TRUNC(X10*4.5%,-1),0)),0) -> 0 | AC10: =IFERROR(IF(AND((DATEDIF(TEXT(LEFT(C10,6),"00-00-00"),$W$2,"Y")>19),(DATEDIF(TEXT(LEFT(C10,6),"00-00-00"),$W$2,"Y")<65)),TRUNC(X10*0.9%,-1),0),0) -> 0 | AD10: =SUM(AA10:AC11) -> 2970 | AE10: =+X10-AD10 -> 397030 | AG10: =IF(ISERROR(DATEDIF((DATEVALUE(LEFT(C10,2)&"-"&MID(C10,3,2)&"-"&MID(C10,5,2))),$W$2,"y")),"",DATEDIF((DATEVALUE(LEFT(C10,2)&"-"&MID(C10,3,2)&"-"&MID(C10,5,2))),$W$2,"y")) | AH10: 1 | AI10: =AI9 -> 1
J11: 1 | P11: 1 | Y11: =IF((F11*W10)>=150000,(F11*W10)-150000,0)+IF((G11*W10)>=150000,(G11*W10)-150000,0)+IF((H11*W10)>=150000,(H11*W10)-150000,0)+IF((I11*W10)>=150000,(I11*W10)-150000,0)+IF((J11*W10)>=150000,(J11*W10)-150000,0)+IF((K11*W10)>=150000,(K11*W10)-150000,0)+IF((L11*W10)>=150000,(L11*W10)-150000,0)+IF((M11*W10)>=150000,(M11*W10)-150000,0)+IF((N11*W10)>=150000,(N11*W10)-150000,0)+IF((O11*W10)>=150000,(O11*W10)-150000,0)+IF((P11*W10)>=150000,(P11*W10)-150000,0)+IF((Q11*W10)>=150000,(Q11*W10)-150000,0)+IF((R11*W10)>=150000,(R11*W10)-150000,0)+IF((S11*W10)>=150000,(S11*W10)-150000,0)+IF((T11*W10)>=150000,(T11*W10)-150000,0)+IF((U11*W10)>=150000,(U11*W10)-150000,0) -> 100000 | AA11: =ROUNDDOWN(AA10*10%,-1) -> 270 | AB11: =IF(V10<8,0,(TRUNC(X10*3.545%,-1))) -> 0 | AC11: =TRUNC(((AB11*12.95%)),-1) -> 0 | AH11: 2 | AI11: =AI10 -> 1
A12: =IF(B12>0,A10+1,"") -> 4 | B12: 김홍석 | V12: =SUM(F12:U13) -> 2 | W12: 250000 | X12: =V12*W12 -> 500000 | Y12: =IF((F12*W12)>=150000,(F12*W12)-150000,0)+IF((G12*W12)>=150000,(G12*W12)-150000,0)+IF((H12*W12)>=150000,(H12*W12)-150000,0)+IF((I12*W12)>=150000,(I12*W12)-150000,0)+IF((J12*W12)>=150000,(J12*W12)-150000,0)+IF((K12*W12)>=150000,(K12*W12)-150000,0)+IF((L12*W12)>=150000,(L12*W12)-150000,0)+IF((M12*W12)>=150000,(M12*W12)-150000,0)+IF((N12*W12)>=150000,(N12*W12)-150000,0)+IF((O12*W12)>=150000,(O12*W12)-150000,0)+IF((P12*W12)>=150000,(P12*W12)-150000,0)+IF((Q12*W12)>=150000,(Q12*W12)-150000,0)+IF((R12*W12)>=150000,(R12*W12)-150000,0)+IF((S12*W12)>=150000,(S12*W12)-150000,0)+IF((T12*W12)>=150000,(T12*W12)-150000,0) -> 0 | Z12: =+Y12+Y13 -> 200000 | AA12: =IF((ROUNDDOWN((+Z12*6%)*45%,-1))>=1000,(ROUNDDOWN((+Z12*6%)*45%,-1)),0) -> 5400 | AB12: =IFERROR(IF(DATEDIF(DATE(MID(C12,1,2),MID(C12,3,2),MID(C12,5,2)),$W$2,"y")>=60,0,IF(OR(V12>=8,X12>=2200000),TRUNC(X12*4.5%,-1),0)),0) -> 0 | AC12: =IFERROR(IF(AND((DATEDIF(TEXT(LEFT(C12,6),"00-00-00"),$W$2,"Y")>19),(DATEDIF(TEXT(LEFT(C12,6),"00-00-00"),$W$2,"Y")<65)),TRUNC(X12*0.9%,-1),0),0) -> 0 | AD12: =SUM(AA12:AC13) -> 5940 | AE12: =+X12-AD12 -> 494060 | AG12: =IF(ISERROR(DATEDIF((DATEVALUE(LEFT(C12,2)&"-"&MID(C12,3,2)&"-"&MID(C12,5,2))),$W$2,"y")),"",DATEDIF((DATEVALUE(LEFT(C12,2)&"-"&MID(C12,3,2)&"-"&MID(C12,5,2))),$W$2,"y")) | AH12: 1 | AI12: =AI11 -> 1
F13: 1 | G13: 1 | Y13: =IF((F13*W12)>=150000,(F13*W12)-150000,0)+IF((G13*W12)>=150000,(G13*W12)-150000,0)+IF((H13*W12)>=150000,(H13*W12)-150000,0)+IF((I13*W12)>=150000,(I13*W12)-150000,0)+IF((J13*W12)>=150000,(J13*W12)-150000,0)+IF((K13*W12)>=150000,(K13*W12)-150000,0)+IF((L13*W12)>=150000,(L13*W12)-150000,0)+IF((M13*W12)>=150000,(M13*W12)-150000,0)+IF((N13*W12)>=150000,(N13*W12)-150000,0)+IF((O13*W12)>=150000,(O13*W12)-150000,0)+IF((P13*W12)>=150000,(P13*W12)-150000,0)+IF((Q13*W12)>=150000,(Q13*W12)-150000,0)+IF((R13*W12)>=150000,(R13*W12)-150000,0)+IF((S13*W12)>=150000,(S13*W12)-150000,0)+IF((T13*W12)>=150000,(T13*W12)-150000,0)+IF((U13*W12)>=150000,(U13*W12)-150000,0) -> 200000 | AA13: =ROUNDDOWN(AA12*10%,-1) -> 540 | AB13: =IF(V12<8,0,(TRUNC(X12*3.545%,-1))) -> 0 | AC13: =TRUNC(((AB13*12.95%)),-1) -> 0 | AH13: 2 | AI13: =AI12 -> 1
A14: =IF(B14>0,A12+1,"") -> 5 | B14: 김희석 | H14: 1 | I14: 1 | J14: 1 | K14: 1 | L14: 1 | N14: 1 | O14: 1 | P14: 1 | Q14: 1 | R14: 1 | S14: 1 | V14: =SUM(F14:U15) -> 24 | W14: 120000 | X14: =V14*W14 -> 2880000 | Y14: =IF((F14*W14)>=150000,(F14*W14)-150000,0)+IF((G14*W14)>=150000,(G14*W14)-150000,0)+IF((H14*W14)>=150000,(H14*W14)-150000,0)+IF((I14*W14)>=150000,(I14*W14)-150000,0)+IF((J14*W14)>=150000,(J14*W14)-150000,0)+IF((K14*W14)>=150000,(K14*W14)-150000,0)+IF((L14*W14)>=150000,(L14*W14)-150000,0)+IF((M14*W14)>=150000,(M14*W14)-150000,0)+IF((N14*W14)>=150000,(N14*W14)-150000,0)+IF((O14*W14)>=150000,(O14*W14)-150000,0)+IF((P14*W14)>=150000,(P14*W14)-150000,0)+IF((Q14*W14)>=150000,(Q14*W14)-150000,0)+IF((R14*W14)>=150000,(R14*W14)-150000,0)+IF((S14*W14)>=150000,(S14*W14)-150000,0)+IF((T14*W14)>=150000,(T14*W14)-150000,0) -> 0 | Z14: =+Y14+Y15 -> 0 | AA14: =IF((ROUNDDOWN((+Z14*6%)*45%,-1))>=1000,(ROUNDDOWN((+Z14*6%)*45%,-1)),0) -> 0 | AB14: =IFERROR(IF(DATEDIF(DATE(MID(C14,1,2),MID(C14,3,2),MID(C14,5,2)),$W$2,"y")>=60,0,IF(OR(V14>=8,X14>=2200000),TRUNC(X14*4.5%,-1),0)),0) -> 0 | AC14: =IFERROR(IF(AND((DATEDIF(TEXT(LEFT(C14,6),"00-00-00"),$W$2,"Y")>19),(DATEDIF(TEXT(LEFT(C14,6),"00-00-00"),$W$2,"Y")<65)),TRUNC(X14*0.9%,-1),0),0) -> 0 | AD14: =SUM(AA14:AC15) -> 115310 | AE14: =+X14-AD14 -> 2764690 | AG14: =IF(ISERROR(DATEDIF((DATEVALUE(LEFT(C14,2)&"-"&MID(C14,3,2)&"-"&MID(C14,5,2))),$W$2,"y")),"",DATEDIF((DATEVALUE(LEFT(C14,2)&"-"&MID(C14,3,2)&"-"&MID(C14,5,2))),$W$2,"y")) | AH14: 1 | AI14: =AI13 -> 1
F15: 1 | G15: 1 | H15: 1 | I15: 1 | J15: 1 | K15: 1 | M15: 1 | N15: 1 | O15: 1 | P15: 1 | Q15: 1 | R15: 1 | T15: 1 | Y15: =IF((F15*W14)>=150000,(F15*W14)-150000,0)+IF((G15*W14)>=150000,(G15*W14)-150000,0)+IF((H15*W14)>=150000,(H15*W14)-150000,0)+IF((I15*W14)>=150000,(I15*W14)-150000,0)+IF((J15*W14)>=150000,(J15*W14)-150000,0)+IF((K15*W14)>=150000,(K15*W14)-150000,0)+IF((L15*W14)>=150000,(L15*W14)-150000,0)+IF((M15*W14)>=150000,(M15*W14)-150000,0)+IF((N15*W14)>=150000,(N15*W14)-150000,0)+IF((O15*W14)>=150000,(O15*W14)-150000,0)+IF((P15*W14)>=150000,(P15*W14)-150000,0)+IF((Q15*W14)>=150000,(Q15*W14)-150000,0)+IF((R15*W14)>=150000,(R15*W14)-150000,0)+IF((S15*W14)>=150000,(S15*W14)-150000,0)+IF((T15*W14)>=150000,(T15*W14)-150000,0)+IF((U15*W14)>=150000,(U15*W14)-150000,0) -> 0 | AA15: =ROUNDDOWN(AA14*10%,-1) -> 0 | AB15: =IF(V14<8,0,(TRUNC(X14*3.545%,-1))) -> 102090 | AC15: =TRUNC(((AB15*12.95%)),-1) -> 13220 | AH15: 2 | AI15: =AI14 -> 1
A16: =IF(B16>0,A14+1,"") -> 6 | B16: 박덕호 | H16: 1 | I16: 1 | J16: 1 | K16: 1 | L16: 1 | N16: 1 | O16: 1 | P16: 1 | Q16: 1 | R16: 1 | V16: =SUM(F16:U17) -> 23 | W16: 150000 | X16: =V16*W16 -> 3450000 | Y16: =IF((F16*W16)>=150000,(F16*W16)-150000,0)+IF((G16*W16)>=150000,(G16*W16)-150000,0)+IF((H16*W16)>=150000,(H16*W16)-150000,0)+IF((I16*W16)>=150000,(I16*W16)-150000,0)+IF((J16*W16)>=150000,(J16*W16)-150000,0)+IF((K16*W16)>=150000,(K16*W16)-150000,0)+IF((L16*W16)>=150000,(L16*W16)-150000,0)+IF((M16*W16)>=150000,(M16*W16)-150000,0)+IF((N16*W16)>=150000,(N16*W16)-150000,0)+IF((O16*W16)>=150000,(O16*W16)-150000,0)+IF((P16*W16)>=150000,(P16*W16)-150000,0)+IF((Q16*W16)>=150000,(Q16*W16)-150000,0)+IF((R16*W16)>=150000,(R16*W16)-150000,0)+IF((S16*W16)>=150000,(S16*W16)-150000,0)+IF((T16*W16)>=150000,(T16*W16)-150000,0) -> 0 | Z16: =+Y16+Y17 -> 0 | AA16: =IF((ROUNDDOWN((+Z16*6%)*45%,-1))>=1000,(ROUNDDOWN((+Z16*6%)*45%,-1)),0) -> 0 | AB16: =IFERROR(IF(DATEDIF(DATE(MID(C16,1,2),MID(C16,3,2),MID(C16,5,2)),$W$2,"y")>=60,0,IF(OR(V16>=8,X16>=2200000),TRUNC(X16*4.5%,-1),0)),0) -> 0 | AC16: =IFERROR(IF(AND((DATEDIF(TEXT(LEFT(C16,6),"00-00-00"),$W$2,"Y")>19),(DATEDIF(TEXT(LEFT(C16,6),"00-00-00"),$W$2,"Y")<65)),TRUNC(X16*0.9%,-1),0),0) -> 0 | AD16: =SUM(AA16:AC17) -> 138130 | AE16: =+X16-AD16 -> 3311870 | AG16: =IF(ISERROR(DATEDIF((DATEVALUE(LEFT(C16,2)&"-"&MID(C16,3,2)&"-"&MID(C16,5,2))),$W$2,"y")),"",DATEDIF((DATEVALUE(LEFT(C16,2)&"-"&MID(C16,3,2)&"-"&MID(C16,5,2))),$W$2,"y")) | AH16: 1 | AI16: =AI15 -> 1
F17: 1 | G17: 1 | H17: 1 | I17: 1 | J17: 1 | K17: 1 | M17: 1 | N17: 1 | O17: 1 | P17: 1 | Q17: 1 | R17: 1 | T17: 1 | Y17: =IF((F17*W16)>=150000,(F17*W16)-150000,0)+IF((G17*W16)>=150000,(G17*W16)-150000,0)+IF((H17*W16)>=150000,(H17*W16)-150000,0)+IF((I17*W16)>=150000,(I17*W16)-150000,0)+IF((J17*W16)>=150000,(J17*W16)-150000,0)+IF((K17*W16)>=150000,(K17*W16)-150000,0)+IF((L17*W16)>=150000,(L17*W16)-150000,0)+IF((M17*W16)>=150000,(M17*W16)-150000,0)+IF((N17*W16)>=150000,(N17*W16)-150000,0)+IF((O17*W16)>=150000,(O17*W16)-150000,0)+IF((P17*W16)>=150000,(P17*W16)-150000,0)+IF((Q17*W16)>=150000,(Q17*W16)-150000,0)+IF((R17*W16)>=150000,(R17*W16)-150000,0)+IF((S17*W16)>=150000,(S17*W16)-150000,0)+IF((T17*W16)>=150000,(T17*W16)-150000,0)+IF((U17*W16)>=150000,(U17*W16)-150000,0) -> 0 | AA17: =ROUNDDOWN(AA16*10%,-1) -> 0 | AB17: =IF(V16<8,0,(TRUNC(X16*3.545%,-1))) -> 122300 | AC17: =TRUNC(((AB17*12.95%)),-1) -> 15830 | AH17: 2 | AI17: =AI16 -> 1
A18: =IF(B18>0,A16+1,"") -> 7 | B18: 박상흠 | H18: 1 | J18: 1 | K18: 1 | L18: 1 | N18: 1 | O18: 1 | R18: 1 | S18: 1 | V18: =SUM(F18:U19) -> 16 | W18: 150000 | X18: =V18*W18 -> 2400000 | Y18: =IF((F18*W18)>=150000,(F18*W18)-150000,0)+IF((G18*W18)>=150000,(G18*W18)-150000,0)+IF((H18*W18)>=150000,(H18*W18)-150000,0)+IF((I18*W18)>=150000,(I18*W18)-150000,0)+IF((J18*W18)>=150000,(J18*W18)-150000,0)+IF((K18*W18)>=150000,(K18*W18)-150000,0)+IF((L18*W18)>=150000,(L18*W18)-150000,0)+IF((M18*W18)>=150000,(M18*W18)-150000,0)+IF((N18*W18)>=150000,(N18*W18)-150000,0)+IF((O18*W18)>=150000,(O18*W18)-150000,0)+IF((P18*W18)>=150000,(P18*W18)-150000,0)+IF((Q18*W18)>=150000,(Q18*W18)-150000,0)+IF((R18*W18)>=150000,(R18*W18)-150000,0)+IF((S18*W18)>=150000,(S18*W18)-150000,0)+IF((T18*W18)>=150000,(T18*W18)-150000,0) -> 0 | Z18: =+Y18+Y19 -> 0 | AA18: =IF((ROUNDDOWN((+Z18*6%)*45%,-1))>=1000,(ROUNDDOWN((+Z18*6%)*45%,-1)),0) -> 0 | AB18: =IFERROR(IF(DATEDIF(DATE(MID(C18,1,2),MID(C18,3,2),MID(C18,5,2)),$W$2,"y")>=60,0,IF(OR(V18>=8,X18>=2200000),TRUNC(X18*4.5%,-1),0)),0) -> 0 | AC18: =IFERROR(IF(AND((DATEDIF(TEXT(LEFT(C18,6),"00-00-00"),$W$2,"Y")>19),(DATEDIF(TEXT(LEFT(C18,6),"00-00-00"),$W$2,"Y")<65)),TRUNC(X18*0.9%,-1),0),0) -> 0 | AD18: =SUM(AA18:AC19) -> 96090 | AE18: =+X18-AD18 -> 2303910 | AG18: =IF(ISERROR(DATEDIF((DATEVALUE(LEFT(C18,2)&"-"&MID(C18,3,2)&"-"&MID(C18,5,2))),$W$2,"y")),"",DATEDIF((DATEVALUE(LEFT(C18,2)&"-"&MID(C18,3,2)&"-"&MID(C18,5,2))),$W$2,"y")) | AH18: 1 | AI18: =AI17 -> 1
F19: 1 | G19: 1 | H19: 1 | I19: 1 | J19: 1 | K19: 1 | M19: 1 | N19: 1 | Y19: =IF((F19*W18)>=150000,(F19*W18)-150000,0)+IF((G19*W18)>=150000,(G19*W18)-150000,0)+IF((H19*W18)>=150000,(H19*W18)-150000,0)+IF((I19*W18)>=150000,(I19*W18)-150000,0)+IF((J19*W18)>=150000,(J19*W18)-150000,0)+IF((K19*W18)>=150000,(K19*W18)-150000,0)+IF((L19*W18)>=150000,(L19*W18)-150000,0)+IF((M19*W18)>=150000,(M19*W18)-150000,0)+IF((N19*W18)>=150000,(N19*W18)-150000,0)+IF((O19*W18)>=150000,(O19*W18)-150000,0)+IF((P19*W18)>=150000,(P19*W18)-150000,0)+IF((Q19*W18)>=150000,(Q19*W18)-150000,0)+IF((R19*W18)>=150000,(R19*W18)-150000,0)+IF((S19*W18)>=150000,(S19*W18)-150000,0)+IF((T19*W18)>=150000,(T19*W18)-150000,0)+IF((U19*W18)>=150000,(U19*W18)-150000,0) -> 0 | AA19: =ROUNDDOWN(AA18*10%,-1) -> 0 | AB19: =IF(V18<8,0,(TRUNC(X18*3.545%,-1))) -> 85080 | AC19: =TRUNC(((AB19*12.95%)),-1) -> 11010 | AH19: 2 | AI19: =AI18 -> 1
A20: =IF(B20>0,A18+1,"") -> 8 | B20: 박영준 | V20: =SUM(F20:U21) -> 8 | W20: 150000 | X20: =V20*W20 -> 1200000 | Y20: =IF((F20*W20)>=150000,(F20*W20)-150000,0)+IF((G20*W20)>=150000,(G20*W20)-150000,0)+IF((H20*W20)>=150000,(H20*W20)-150000,0)+IF((I20*W20)>=150000,(I20*W20)-150000,0)+IF((J20*W20)>=150000,(J20*W20)-150000,0)+IF((K20*W20)>=150000,(K20*W20)-150000,0)+IF((L20*W20)>=150000,(L20*W20)-150000,0)+IF((M20*W20)>=150000,(M20*W20)-150000,0)+IF((N20*W20)>=150000,(N20*W20)-150000,0)+IF((O20*W20)>=150000,(O20*W20)-150000,0)+IF((P20*W20)>=150000,(P20*W20)-150000,0)+IF((Q20*W20)>=150000,(Q20*W20)-150000,0)+IF((R20*W20)>=150000,(R20*W20)-150000,0)+IF((S20*W20)>=150000,(S20*W20)-150000,0)+IF((T20*W20)>=150000,(T20*W20)-150000,0) -> 0 | Z20: =+Y20+Y21 -> 0 | AA20: =IF((ROUNDDOWN((+Z20*6%)*45%,-1))>=1000,(ROUNDDOWN((+Z20*6%)*45%,-1)),0) -> 0 | AB20: =IFERROR(IF(DATEDIF(DATE(MID(C20,1,2),MID(C20,3,2),MID(C20,5,2)),$W$2,"y")>=60,0,IF(OR(V20>=8,X20>=2200000),TRUNC(X20*4.5%,-1),0)),0) -> 0 | AC20: =IFERROR(IF(AND((DATEDIF(TEXT(LEFT(C20,6),"00-00-00"),$W$2,"Y")>19),(DATEDIF(TEXT(LEFT(C20,6),"00-00-00"),$W$2,"Y")<65)),TRUNC(X20*0.9%,-1),0),0) -> 0 | AD20: =SUM(AA20:AC21) -> 48040 | AE20: =+X20-AD20 -> 1151960 | AG20: =IF(ISERROR(DATEDIF((DATEVALUE(LEFT(C20,2)&"-"&MID(C20,3,2)&"-"&MID(C20,5,2))),$W$2,"y")),"",DATEDIF((DATEVALUE(LEFT(C20,2)&"-"&MID(C20,3,2)&"-"&MID(C20,5,2))),$W$2,"y")) | AH20: 1 | AI20: =AI19 -> 1
H21: 1 | I21: 1 | J21: 1 | K21: 1 | M21: 1 | N21: 1 | O21: 1 | P21: 1 | Y21: =IF((F21*W20)>=150000,(F21*W20)-150000,0)+IF((G21*W20)>=150000,(G21*W20)-150000,0)+IF((H21*W20)>=150000,(H21*W20)-150000,0)+IF((I21*W20)>=150000,(I21*W20)-150000,0)+IF((J21*W20)>=150000,(J21*W20)-150000,0)+IF((K21*W20)>=150000,(K21*W20)-150000,0)+IF((L21*W20)>=150000,(L21*W20)-150000,0)+IF((M21*W20)>=150000,(M21*W20)-150000,0)+IF((N21*W20)>=150000,(N21*W20)-150000,0)+IF((O21*W20)>=150000,(O21*W20)-150000,0)+IF((P21*W20)>=150000,(P21*W20)-150000,0)+IF((Q21*W20)>=150000,(Q21*W20)-150000,0)+IF((R21*W20)>=150000,(R21*W20)-150000,0)+IF((S21*W20)>=150000,(S21*W20)-150000,0)+IF((T21*W20)>=150000,(T21*W20)-150000,0)+IF((U21*W20)>=150000,(U21*W20)-150000,0) -> 0 | AA21: =ROUNDDOWN(AA20*10%,-1) -> 0 | AB21: =IF(V20<8,0,(TRUNC(X20*3.545%,-1))) -> 42540 | AC21: =TRUNC(((AB21*12.95%)),-1) -> 5500 | AH21: 2 | AI21: =AI20 -> 1
A22: =IF(B22>0,A20+1,"") -> 9 | B22: 박창준 | H22: 1 | K22: 1 | L22: 1 | V22: =SUM(F22:U23) -> 8 | W22: 150000 | X22: =V22*W22 -> 1200000 | Y22: =IF((F22*W22)>=150000,(F22*W22)-150000,0)+IF((G22*W22)>=150000,(G22*W22)-150000,0)+IF((H22*W22)>=150000,(H22*W22)-150000,0)+IF((I22*W22)>=150000,(I22*W22)-150000,0)+IF((J22*W22)>=150000,(J22*W22)-150000,0)+IF((K22*W22)>=150000,(K22*W22)-150000,0)+IF((L22*W22)>=150000,(L22*W22)-150000,0)+IF((M22*W22)>=150000,(M22*W22)-150000,0)+IF((N22*W22)>=150000,(N22*W22)-150000,0)+IF((O22*W22)>=150000,(O22*W22)-150000,0)+IF((P22*W22)>=150000,(P22*W22)-150000,0)+IF((Q22*W22)>=150000,(Q22*W22)-150000,0)+IF((R22*W22)>=150000,(R22*W22)-150000,0)+IF((S22*W22)>=150000,(S22*W22)-150000,0)+IF((T22*W22)>=150000,(T22*W22)-150000,0) -> 0 | Z22: =+Y22+Y23 -> 0 | AA22: =IF((ROUNDDOWN((+Z22*6%)*45%,-1))>=1000,(ROUNDDOWN((+Z22*6%)*45%,-1)),0) -> 0 | AB22: =IFERROR(IF(DATEDIF(DATE(MID(C22,1,2),MID(C22,3,2),MID(C22,5,2)),$W$2,"y")>=60,0,IF(OR(V22>=8,X22>=2200000),TRUNC(X22*4.5%,-1),0)),0) -> 0 | AC22: =IFERROR(IF(AND((DATEDIF(TEXT(LEFT(C22,6),"00-00-00"),$W$2,"Y")>19),(DATEDIF(TEXT(LEFT(C22,6),"00-00-00"),$W$2,"Y")<65)),TRUNC(X22*0.9%,-1),0),0) -> 0 | AD22: =SUM(AA22:AC23) -> 48040 | AE22: =+X22-AD22 -> 1151960 | AG22: =IF(ISERROR(DATEDIF((DATEVALUE(LEFT(C22,2)&"-"&MID(C22,3,2)&"-"&MID(C22,5,2))),$W$2,"y")),"",DATEDIF((DATEVALUE(LEFT(C22,2)&"-"&MID(C22,3,2)&"-"&MID(C22,5,2))),$W$2,"y")) | AH22: 1 | AI22: =AI21 -> 1
H23: 1 | I23: 1 | J23: 1 | K23: 1 | M23: 1 | Y23: =IF((F23*W22)>=150000,(F23*W22)-150000,0)+IF((G23*W22)>=150000,(G23*W22)-150000,0)+IF((H23*W22)>=150000,(H23*W22)-150000,0)+IF((I23*W22)>=150000,(I23*W22)-150000,0)+IF((J23*W22)>=150000,(J23*W22)-150000,0)+IF((K23*W22)>=150000,(K23*W22)-150000,0)+IF((L23*W22)>=150000,(L23*W22)-150000,0)+IF((M23*W22)>=150000,(M23*W22)-150000,0)+IF((N23*W22)>=150000,(N23*W22)-150000,0)+IF((O23*W22)>=150000,(O23*W22)-150000,0)+IF((P23*W22)>=150000,(P23*W22)-150000,0)+IF((Q23*W22)>=150000,(Q23*W22)-150000,0)+IF((R23*W22)>=150000,(R23*W22)-150000,0)+IF((S23*W22)>=150000,(S23*W22)-150000,0)+IF((T23*W22)>=150000,(T23*W22)-150000,0)+IF((U23*W22)>=150000,(U23*W22)-150000,0) -> 0 | AA23: =ROUNDDOWN(AA22*10%,-1) -> 0 | AB23: =IF(V22<8,0,(TRUNC(X22*3.545%,-1))) -> 42540 | AC23: =TRUNC(((AB23*12.95%)),-1) -> 5500 | AH23: 2 | AI23: =AI22 -> 1
A24: =IF(B24>0,A22+1,"") -> 10 | B24: 박창현 | V24: =SUM(F24:U25) -> 5 | W24: 200000 | X24: =V24*W24 -> 1000000 | Y24: =IF((F24*W24)>=150000,(F24*W24)-150000,0)+IF((G24*W24)>=150000,(G24*W24)-150000,0)+IF((H24*W24)>=150000,(H24*W24)-150000,0)+IF((I24*W24)>=150000,(I24*W24)-150000,0)+IF((J24*W24)>=150000,(J24*W24)-150000,0)+IF((K24*W24)>=150000,(K24*W24)-150000,0)+IF((L24*W24)>=150000,(L24*W24)-150000,0)+IF((M24*W24)>=150000,(M24*W24)-150000,0)+IF((N24*W24)>=150000,(N24*W24)-150000,0)+IF((O24*W24)>=150000,(O24*W24)-150000,0)+IF((P24*W24)>=150000,(P24*W24)-150000,0)+IF((Q24*W24)>=150000,(Q24*W24)-150000,0)+IF((R24*W24)>=150000,(R24*W24)-150000,0)+IF((S24*W24)>=150000,(S24*W24)-150000,0)+IF((T24*W24)>=150000,(T24*W24)-150000,0) -> 0 | Z24: =+Y24+Y25 -> 250000 | AA24: =IF((ROUNDDOWN((+Z24*6%)*45%,-1))>=1000,(ROUNDDOWN((+Z24*6%)*45%,-1)),0) -> 6750 | AB24: =IFERROR(IF(DATEDIF(DATE(MID(C24,1,2),MID(C24,3,2),MID(C24,5,2)),$W$2,"y")>=60,0,IF(OR(V24>=8,X24>=2200000),TRUNC(X24*4.5%,-1),0)),0) -> 0 | AC24: =IFERROR(IF(AND((DATEDIF(TEXT(LEFT(C24,6),"00-00-00"),$W$2,"Y")>19),(DATEDIF(TEXT(LEFT(C24,6),"00-00-00"),$W$2,"Y")<65)),TRUNC(X24*0.9%,-1),0),0) -> 0 | AD24: =SUM(AA24:AC25) -> 7420 | AE24: =+X24-AD24 -> 992580 | AG24: =IF(ISERROR(DATEDIF((DATEVALUE(LEFT(C24,2)&"-"&MID(C24,3,2)&"-"&MID(C24,5,2))),$W$2,"y")),"",DATEDIF((DATEVALUE(LEFT(C24,2)&"-"&MID(C24,3,2)&"-"&MID(C24,5,2))),$W$2,"y")) | AH24: 1 | AI24: =AI23 -> 1
H25: 1 | I25: 1 | J25: 1 | M25: 1 | N25: 1 | Y25: =IF((F25*W24)>=150000,(F25*W24)-150000,0)+IF((G25*W24)>=150000,(G25*W24)-150000,0)+IF((H25*W24)>=150000,(H25*W24)-150000,0)+IF((I25*W24)>=150000,(I25*W24)-150000,0)+IF((J25*W24)>=150000,(J25*W24)-150000,0)+IF((K25*W24)>=150000,(K25*W24)-150000,0)+IF((L25*W24)>=150000,(L25*W24)-150000,0)+IF((M25*W24)>=150000,(M25*W24)-150000,0)+IF((N25*W24)>=150000,(N25*W24)-150000,0)+IF((O25*W24)>=150000,(O25*W24)-150000,0)+IF((P25*W24)>=150000,(P25*W24)-150000,0)+IF((Q25*W24)>=150000,(Q25*W24)-150000,0)+IF((R25*W24)>=150000,(R25*W24)-150000,0)+IF((S25*W24)>=150000,(S25*W24)-150000,0)+IF((T25*W24)>=150000,(T25*W24)-150000,0)+IF((U25*W24)>=150000,(U25*W24)-150000,0) -> 250000 | AA25: =ROUNDDOWN(AA24*10%,-1) -> 670 | AB25: =IF(V24<8,0,(TRUNC(X24*3.545%,-1))) -> 0 | AC25: =TRUNC(((AB25*12.95%)),-1) -> 0 | AH25: 2 | AI25: =AI24 -> 1
A26: =IF(B26>0,A24+1,"") -> 11 | B26: 서종태 | V26: =SUM(F26:U27) -> 1 | W26: 200000 | X26: =V26*W26 -> 200000 | Y26: =IF((F26*W26)>=150000,(F26*W26)-150000,0)+IF((G26*W26)>=150000,(G26*W26)-150000,0)+IF((H26*W26)>=150000,(H26*W26)-150000,0)+IF((I26*W26)>=150000,(I26*W26)-150000,0)+IF((J26*W26)>=150000,(J26*W26)-150000,0)+IF((K26*W26)>=150000,(K26*W26)-150000,0)+IF((L26*W26)>=150000,(L26*W26)-150000,0)+IF((M26*W26)>=150000,(M26*W26)-150000,0)+IF((N26*W26)>=150000,(N26*W26)-150000,0)+IF((O26*W26)>=150000,(O26*W26)-150000,0)+IF((P26*W26)>=150000,(P26*W26)-150000,0)+IF((Q26*W26)>=150000,(Q26*W26)-150000,0)+IF((R26*W26)>=150000,(R26*W26)-150000,0)+IF((S26*W26)>=150000,(S26*W26)-150000,0)+IF((T26*W26)>=150000,(T26*W26)-150000,0) -> 0 | Z26: =+Y26+Y27 -> 50000 | AA26: =IF((ROUNDDOWN((+Z26*6%)*45%,-1))>=1000,(ROUNDDOWN((+Z26*6%)*45%,-1)),0) -> 1350 | AB26: =IFERROR(IF(DATEDIF(DATE(MID(C26,1,2),MID(C26,3,2),MID(C26,5,2)),$W$2,"y")>=60,0,IF(OR(V26>=8,X26>=2200000),TRUNC(X26*4.5%,-1),0)),0) -> 0 | AC26: =IFERROR(IF(AND((DATEDIF(TEXT(LEFT(C26,6),"00-00-00"),$W$2,"Y")>19),(DATEDIF(TEXT(LEFT(C26,6),"00-00-00"),$W$2,"Y")<65)),TRUNC(X26*0.9%,-1),0),0) -> 0 | AD26: =SUM(AA26:AC27) -> 1480 | AE26: =+X26-AD26 -> 198520 | AG26: =IF(ISERROR(DATEDIF((DATEVALUE(LEFT(C26,2)&"-"&MID(C26,3,2)&"-"&MID(C26,5,2))),$W$2,"y")),"",DATEDIF((DATEVALUE(LEFT(C26,2)&"-"&MID(C26,3,2)&"-"&MID(C26,5,2))),$W$2,"y")) | AH26: 1 | AI26: =AI25 -> 1
M27: 1 | Y27: =IF((F27*W26)>=150000,(F27*W26)-150000,0)+IF((G27*W26)>=150000,(G27*W26)-150000,0)+IF((H27*W26)>=150000,(H27*W26)-150000,0)+IF((I27*W26)>=150000,(I27*W26)-150000,0)+IF((J27*W26)>=150000,(J27*W26)-150000,0)+IF((K27*W26)>=150000,(K27*W26)-150000,0)+IF((L27*W26)>=150000,(L27*W26)-150000,0)+IF((M27*W26)>=150000,(M27*W26)-150000,0)+IF((N27*W26)>=150000,(N27*W26)-150000,0)+IF((O27*W26)>=150000,(O27*W26)-150000,0)+IF((P27*W26)>=150000,(P27*W26)-150000,0)+IF((Q27*W26)>=150000,(Q27*W26)-150000,0)+IF((R27*W26)>=150000,(R27*W26)-150000,0)+IF((S27*W26)>=150000,(S27*W26)-150000,0)+IF((T27*W26)>=150000,(T27*W26)-150000,0)+IF((U27*W26)>=150000,(U27*W26)-150000,0) -> 50000 | AA27: =ROUNDDOWN(AA26*10%,-1) -> 130 | AB27: =IF(V26<8,0,(TRUNC(X26*3.545%,-1))) -> 0 | AC27: =TRUNC(((AB27*12.95%)),-1) -> 0 | AH27: 2 | AI27: =AI26 -> 1
A28: =IF(B28>0,A26+1,"") -> 12 | B28: 이경란 | I28: 1 | J28: 1 | N28: 1 | O28: 1 | R28: 1 | S28: 1 | V28: =SUM(F28:U29) -> 13 | W28: 150000 | X28: =V28*W28 -> 1950000 | Y28: =IF((F28*W28)>=150000,(F28*W28)-150000,0)+IF((G28*W28)>=150000,(G28*W28)-150000,0)+IF((H28*W28)>=150000,(H28*W28)-150000,0)+IF((I28*W28)>=150000,(I28*W28)-150000,0)+IF((J28*W28)>=150000,(J28*W28)-150000,0)+IF((K28*W28)>=150000,(K28*W28)-150000,0)+IF((L28*W28)>=150000,(L28*W28)-150000,0)+IF((M28*W28)>=150000,(M28*W28)-150000,0)+IF((N28*W28)>=150000,(N28*W28)-150000,0)+IF((O28*W28)>=150000,(O28*W28)-150000,0)+IF((P28*W28)>=150000,(P28*W28)-150000,0)+IF((Q28*W28)>=150000,(Q28*W28)-150000,0)+IF((R28*W28)>=150000,(R28*W28)-150000,0)+IF((S28*W28)>=150000,(S28*W28)-150000,0)+IF((T28*W28)>=150000,(T28*W28)-150000,0) -> 0 | Z28: =+Y28+Y29 -> 0 | AA28: =IF((ROUNDDOWN((+Z28*6%)*45%,-1))>=1000,(ROUNDDOWN((+Z28*6%)*45%,-1)),0) -> 0 | AB28: =IFERROR(IF(DATEDIF(DATE(MID(C28,1,2),MID(C28,3,2),MID(C28,5,2)),$W$2,"y")>=60,0,IF(OR(V28>=8,X28>=2200000),TRUNC(X28*4.5%,-1),0)),0) -> 0 | AC28: =IFERROR(IF(AND((DATEDIF(TEXT(LEFT(C28,6),"00-00-00"),$W$2,"Y")>19),(DATEDIF(TEXT(LEFT(C28,6),"00-00-00"),$W$2,"Y")<65)),TRUNC(X28*0.9%,-1),0),0) -> 0 | AD28: =SUM(AA28:AC29) -> 78070 | AE28: =+X28-AD28 -> 1871930 | AG28: =IF(ISERROR(DATEDIF((DATEVALUE(LEFT(C28,2)&"-"&MID(C28,3,2)&"-"&MID(C28,5,2))),$W$2,"y")),"",DATEDIF((DATEVALUE(LEFT(C28,2)&"-"&MID(C28,3,2)&"-"&MID(C28,5,2))),$W$2,"y")) | AH28: 1 | AI28: =AI27 -> 1
F29: 1 | G29: 1 | H29: 1 | I29: 1 | J29: 1 | K29: 1 | M29: 1 | Y29: =IF((F29*W28)>=150000,(F29*W28)-150000,0)+IF((G29*W28)>=150000,(G29*W28)-150000,0)+IF((H29*W28)>=150000,(H29*W28)-150000,0)+IF((I29*W28)>=150000,(I29*W28)-150000,0)+IF((J29*W28)>=150000,(J29*W28)-150000,0)+IF((K29*W28)>=150000,(K29*W28)-150000,0)+IF((L29*W28)>=150000,(L29*W28)-150000,0)+IF((M29*W28)>=150000,(M29*W28)-150000,0)+IF((N29*W28)>=150000,(N29*W28)-150000,0)+IF((O29*W28)>=150000,(O29*W28)-150000,0)+IF((P29*W28)>=150000,(P29*W28)-150000,0)+IF((Q29*W28)>=150000,(Q29*W28)-150000,0)+IF((R29*W28)>=150000,(R29*W28)-150000,0)+IF((S29*W28)>=150000,(S29*W28)-150000,0)+IF((T29*W28)>=150000,(T29*W28)-150000,0)+IF((U29*W28)>=150000,(U29*W28)-150000,0) -> 0 | AA29: =ROUNDDOWN(AA28*10%,-1) -> 0 | AB29: =IF(V28<8,0,(TRUNC(X28*3.545%,-1))) -> 69120 | AC29: =TRUNC(((AB29*12.95%)),-1) -> 8950 | AH29: 2 | AI29: =AI28 -> 1
A30: =IF(B30>0,A28+1,"") -> 13 | B30: 김길홍 | H30: 1 | I30: 1 | J30: 1 | N30: 1 | O30: 1 | P30: 1 | Q30: 1 | R30: 1 | S30: 1 | V30: =SUM(F30:U31) -> 20 | W30: 180000 | X30: =V30*W30 -> 3600000 | Y30: =IF((F30*W30)>=150000,(F30*W30)-150000,0)+IF((G30*W30)>=150000,(G30*W30)-150000,0)+IF((H30*W30)>=150000,(H30*W30)-150000,0)+IF((I30*W30)>=150000,(I30*W30)-150000,0)+IF((J30*W30)>=150000,(J30*W30)-150000,0)+IF((K30*W30)>=150000,(K30*W30)-150000,0)+IF((L30*W30)>=150000,(L30*W30)-150000,0)+IF((M30*W30)>=150000,(M30*W30)-150000,0)+IF((N30*W30)>=150000,(N30*W30)-150000,0)+IF((O30*W30)>=150000,(O30*W30)-150000,0)+IF((P30*W30)>=150000,(P30*W30)-150000,0)+IF((Q30*W30)>=150000,(Q30*W30)-150000,0)+IF((R30*W30)>=150000,(R30*W30)-150000,0)+IF((S30*W30)>=150000,(S30*W30)-150000,0)+IF((T30*W30)>=150000,(T30*W30)-150000,0) -> 270000 | Z30: =+Y30+Y31 -> 600000 | AA30: =IF((ROUNDDOWN((+Z30*6%)*45%,-1))>=1000,(ROUNDDOWN((+Z30*6%)*45%,-1)),0) -> 16200 | AB30: =IFERROR(IF(DATEDIF(DATE(MID(C30,1,2),MID(C30,3,2),MID(C30,5,2)),$W$2,"y")>=60,0,IF(OR(V30>=8,X30>=2200000),TRUNC(X30*4.5%,-1),0)),0) -> 0 | AC30: =IFERROR(IF(AND((DATEDIF(TEXT(LEFT(C30,6),"00-00-00"),$W$2,"Y")>19),(DATEDIF(TEXT(LEFT(C30,6),"00-00-00"),$W$2,"Y")<65)),TRUNC(X30*0.9%,-1),0),0) -> 0 | AD30: =SUM(AA30:AC31) -> 161960 | AE30: =+X30-AD30 -> 3438040 | AG30: =IF(ISERROR(DATEDIF((DATEVALUE(LEFT(C30,2)&"-"&MID(C30,3,2)&"-"&MID(C30,5,2))),$W$2,"y")),"",DATEDIF((DATEVALUE(LEFT(C30,2)&"-"&MID(C30,3,2)&"-"&MID(C30,5,2))),$W$2,"y")) | AH30: 1 | AI30: =AI29 -> 1
F31: 1 | G31: 1 | H31: 1 | I31: 1 | J31: 1 | K31: 1 | M31: 1 | N31: 1 | O31: 1 | P31: 1 | Q31: 1 | Y31: =IF((F31*W30)>=150000,(F31*W30)-150000,0)+IF((G31*W30)>=150000,(G31*W30)-150000,0)+IF((H31*W30)>=150000,(H31*W30)-150000,0)+IF((I31*W30)>=150000,(I31*W30)-150000,0)+IF((J31*W30)>=150000,(J31*W30)-150000,0)+IF((K31*W30)>=150000,(K31*W30)-150000,0)+IF((L31*W30)>=150000,(L31*W30)-150000,0)+IF((M31*W30)>=150000,(M31*W30)-150000,0)+IF((N31*W30)>=150000,(N31*W30)-150000,0)+IF((O31*W30)>=150000,(O31*W30)-150000,0)+IF((P31*W30)>=150000,(P31*W30)-150000,0)+IF((Q31*W30)>=150000,(Q31*W30)-150000,0)+IF((R31*W30)>=150000,(R31*W30)-150000,0)+IF((S31*W30)>=150000,(S31*W30)-150000,0)+IF((T31*W30)>=150000,(T31*W30)-150000,0)+IF((U31*W30)>=150000,(U31*W30)-150000,0) -> 330000 | AA31: =ROUNDDOWN(AA30*10%,-1) -> 1620 | AB31: =IF(V30<8,0,(TRUNC(X30*3.545%,-1))) -> 127620 | AC31: =TRUNC(((AB31*12.95%)),-1) -> 16520 | AH31: 2 | AI31: =AI30 -> 1
A32: =IF(B32>0,A30+1,"") -> 14 | B32: 김재일 | I32: 1 | V32: =SUM(F32:U33) -> 1 | W32: 180000 | X32: =V32*W32 -> 180000 | Y32: =IF((F32*W32)>=150000,(F32*W32)-150000,0)+IF((G32*W32)>=150000,(G32*W32)-150000,0)+IF((H32*W32)>=150000,(H32*W32)-150000,0)+IF((I32*W32)>=150000,(I32*W32)-150000,0)+IF((J32*W32)>=150000,(J32*W32)-150000,0)+IF((K32*W32)>=150000,(K32*W32)-150000,0)+IF((L32*W32)>=150000,(L32*W32)-150000,0)+IF((M32*W32)>=150000,(M32*W32)-150000,0)+IF((N32*W32)>=150000,(N32*W32)-150000,0)+IF((O32*W32)>=150000,(O32*W32)-150000,0)+IF((P32*W32)>=150000,(P32*W32)-150000,0)+IF((Q32*W32)>=150000,(Q32*W32)-150000,0)+IF((R32*W32)>=150000,(R32*W32)-150000,0)+IF((S32*W32)>=150000,(S32*W32)-150000,0)+IF((T32*W32)>=150000,(T32*W32)-150000,0) -> 30000 | Z32: =+Y32+Y33 -> 30000 | AA32: =IF((ROUNDDOWN((+Z32*6%)*45%,-1))>=1000,(ROUNDDOWN((+Z32*6%)*45%,-1)),0) -> 0 | AB32: =IFERROR(IF(DATEDIF(DATE(MID(C32,1,2),MID(C32,3,2),MID(C32,5,2)),$W$2,"y")>=60,0,IF(OR(V32>=8,X32>=2200000),TRUNC(X32*4.5%,-1),0)),0) -> 0 | AC32: =IFERROR(IF(AND((DATEDIF(TEXT(LEFT(C32,6),"00-00-00"),$W$2,"Y")>19),(DATEDIF(TEXT(LEFT(C32,6),"00-00-00"),$W$2,"Y")<65)),TRUNC(X32*0.9%,-1),0),0) -> 0 | AD32: =SUM(AA32:AC33) -> 0 | AE32: =+X32-AD32 -> 180000 | AG32: =IF(ISERROR(DATEDIF((DATEVALUE(LEFT(C32,2)&"-"&MID(C32,3,2)&"-"&MID(C32,5,2))),$W$2,"y")),"",DATEDIF((DATEVALUE(LEFT(C32,2)&"-"&MID(C32,3,2)&"-"&MID(C32,5,2))),$W$2,"y")) | AH32: 1 | AI32: =AI31 -> 1
Y33: =IF((F33*W32)>=150000,(F33*W32)-150000,0)+IF((G33*W32)>=150000,(G33*W32)-150000,0)+IF((H33*W32)>=150000,(H33*W32)-150000,0)+IF((I33*W32)>=150000,(I33*W32)-150000,0)+IF((J33*W32)>=150000,(J33*W32)-150000,0)+IF((K33*W32)>=150000,(K33*W32)-150000,0)+IF((L33*W32)>=150000,(L33*W32)-150000,0)+IF((M33*W32)>=150000,(M33*W32)-150000,0)+IF((N33*W32)>=150000,(N33*W32)-150000,0)+IF((O33*W32)>=150000,(O33*W32)-150000,0)+IF((P33*W32)>=150000,(P33*W32)-150000,0)+IF((Q33*W32)>=150000,(Q33*W32)-150000,0)+IF((R33*W32)>=150000,(R33*W32)-150000,0)+IF((S33*W32)>=150000,(S33*W32)-150000,0)+IF((T33*W32)>=150000,(T33*W32)-150000,0)+IF((U33*W32)>=150000,(U33*W32)-150000,0) -> 0 | AA33: =ROUNDDOWN(AA32*10%,-1) -> 0 | AB33: =IF(V32<8,0,(TRUNC(X32*3.545%,-1))) -> 0 | AC33: =TRUNC(((AB33*12.95%)),-1) -> 0 | AH33: 2 | AI33: =AI32 -> 1
A34: =IF(B34>0,A32+1,"") -> 15 | B34: 박세찬 | N34: 1 | O34: 1 | P34: 1 | R34: 1 | V34: =SUM(F34:U35) -> 13 | W34: 180000 | X34: =V34*W34 -> 2340000 | Y34: =IF((F34*W34)>=150000,(F34*W34)-150000,0)+IF((G34*W34)>=150000,(G34*W34)-150000,0)+IF((H34*W34)>=150000,(H34*W34)-150000,0)+IF((I34*W34)>=150000,(I34*W34)-150000,0)+IF((J34*W34)>=150000,(J34*W34)-150000,0)+IF((K34*W34)>=150000,(K34*W34)-150000,0)+IF((L34*W34)>=150000,(L34*W34)-150000,0)+IF((M34*W34)>=150000,(M34*W34)-150000,0)+IF((N34*W34)>=150000,(N34*W34)-150000,0)+IF((O34*W34)>=150000,(O34*W34)-150000,0)+IF((P34*W34)>=150000,(P34*W34)-150000,0)+IF((Q34*W34)>=150000,(Q34*W34)-150000,0)+IF((R34*W34)>=150000,(R34*W34)-150000,0)+IF((S34*W34)>=150000,(S34*W34)-150000,0)+IF((T34*W34)>=150000,(T34*W34)-150000,0) -> 120000 | Z34: =+Y34+Y35 -> 390000 | AA34: =IF((ROUNDDOWN((+Z34*6%)*45%,-1))>=1000,(ROUNDDOWN((+Z34*6%)*45%,-1)),0) -> 10530 | AB34: =IFERROR(IF(DATEDIF(DATE(MID(C34,1,2),MID(C34,3,2),MID(C34,5,2)),$W$2,"y")>=60,0,IF(OR(V34>=8,X34>=2200000),TRUNC(X34*4.5%,-1),0)),0) -> 0 | AC34: =IFERROR(IF(AND((DATEDIF(TEXT(LEFT(C34,6),"00-00-00"),$W$2,"Y")>19),(DATEDIF(TEXT(LEFT(C34,6),"00-00-00"),$W$2,"Y")<65)),TRUNC(X34*0.9%,-1),0),0) -> 0 | AD34: =SUM(AA34:AC35) -> 105270 | AE34: =+X34-AD34 -> 2234730 | AG34: =IF(ISERROR(DATEDIF((DATEVALUE(LEFT(C34,2)&"-"&MID(C34,3,2)&"-"&MID(C34,5,2))),$W$2,"y")),"",DATEDIF((DATEVALUE(LEFT(C34,2)&"-"&MID(C34,3,2)&"-"&MID(C34,5,2))),$W$2,"y")) | AH34: 1 | AI34: =AI33 -> 1
F35: 1 | G35: 1 | H35: 1 | I35: 1 | J35: 1 | K35: 1 | M35: 1 | N35: 1 | O35: 1 | Y35: =IF((F35*W34)>=150000,(F35*W34)-150000,0)+IF((G35*W34)>=150000,(G35*W34)-150000,0)+IF((H35*W34)>=150000,(H35*W34)-150000,0)+IF((I35*W34)>=150000,(I35*W34)-150000,0)+IF((J35*W34)>=150000,(J35*W34)-150000,0)+IF((K35*W34)>=150000,(K35*W34)-150000,0)+IF((L35*W34)>=150000,(L35*W34)-150000,0)+IF((M35*W34)>=150000,(M35*W34)-150000,0)+IF((N35*W34)>=150000,(N35*W34)-150000,0)+IF((O35*W34)>=150000,(O35*W34)-150000,0)+IF((P35*W34)>=150000,(P35*W34)-150000,0)+IF((Q35*W34)>=150000,(Q35*W34)-150000,0)+IF((R35*W34)>=150000,(R35*W34)-150000,0)+IF((S35*W34)>=150000,(S35*W34)-150000,0)+IF((T35*W34)>=150000,(T35*W34)-150000,0)+IF((U35*W34)>=150000,(U35*W34)-150000,0) -> 270000 | AA35: =ROUNDDOWN(AA34*10%,-1) -> 1050 | AB35: =IF(V34<8,0,(TRUNC(X34*3.545%,-1))) -> 82950 | AC35: =TRUNC(((AB35*12.95%)),-1) -> 10740 | AH35: 2 | AI35: =AI34 -> 1
A36: =IF(B36>0,A34+1,"") -> 16 | B36: 박현광 | V36: =SUM(F36:U37) -> 4 | W36: 180000 | X36: =V36*W36 -> 720000 | Y36: =IF((F36*W36)>=150000,(F36*W36)-150000,0)+IF((G36*W36)>=150000,(G36*W36)-150000,0)+IF((H36*W36)>=150000,(H36*W36)-150000,0)+IF((I36*W36)>=150000,(I36*W36)-150000,0)+IF((J36*W36)>=150000,(J36*W36)-150000,0)+IF((K36*W36)>=150000,(K36*W36)-150000,0)+IF((L36*W36)>=150000,(L36*W36)-150000,0)+IF((M36*W36)>=150000,(M36*W36)-150000,0)+IF((N36*W36)>=150000,(N36*W36)-150000,0)+IF((O36*W36)>=150000,(O36*W36)-150000,0)+IF((P36*W36)>=150000,(P36*W36)-150000,0)+IF((Q36*W36)>=150000,(Q36*W36)-150000,0)+IF((R36*W36)>=150000,(R36*W36)-150000,0)+IF((S36*W36)>=150000,(S36*W36)-150000,0)+IF((T36*W36)>=150000,(T36*W36)-150000,0) -> 0 | Z36: =+Y36+Y37 -> 120000 | AA36: =IF((ROUNDDOWN((+Z36*6%)*45%,-1))>=1000,(ROUNDDOWN((+Z36*6%)*45%,-1)),0) -> 3240 | AB36: =IFERROR(IF(DATEDIF(DATE(MID(C36,1,2),MID(C36,3,2),MID(C36,5,2)),$W$2,"y")>=60,0,IF(OR(V36>=8,X36>=2200000),TRUNC(X36*4.5%,-1),0)),0) -> 0 | AC36: =IFERROR(IF(AND((DATEDIF(TEXT(LEFT(C36,6),"00-00-00"),$W$2,"Y")>19),(DATEDIF(TEXT(LEFT(C36,6),"00-00-00"),$W$2,"Y")<65)),TRUNC(X36*0.9%,-1),0),0) -> 0 | AD36: =SUM(AA36:AC37) -> 3560 | AE36: =+X36-AD36 -> 716440 | AG36: =IF(ISERROR(DATEDIF((DATEVALUE(LEFT(C36,2)&"-"&MID(C36,3,2)&"-"&MID(C36,5,2))),$W$2,"y")),"",DATEDIF((DATEVALUE(LEFT(C36,2)&"-"&MID(C36,3,2)&"-"&MID(C36,5,2))),$W$2,"y")) | AH36: 1 | AI36: =AI35 -> 1
F37: 1 | G37: 1 | N37: 1 | T37: 1 | Y37: =IF((F37*W36)>=150000,(F37*W36)-150000,0)+IF((G37*W36)>=150000,(G37*W36)-150000,0)+IF((H37*W36)>=150000,(H37*W36)-150000,0)+IF((I37*W36)>=150000,(I37*W36)-150000,0)+IF((J37*W36)>=150000,(J37*W36)-150000,0)+IF((K37*W36)>=150000,(K37*W36)-150000,0)+IF((L37*W36)>=150000,(L37*W36)-150000,0)+IF((M37*W36)>=150000,(M37*W36)-150000,0)+IF((N37*W36)>=150000,(N37*W36)-150000,0)+IF((O37*W36)>=150000,(O37*W36)-150000,0)+IF((P37*W36)>=150000,(P37*W36)-150000,0)+IF((Q37*W36)>=150000,(Q37*W36)-150000,0)+IF((R37*W36)>=150000,(R37*W36)-150000,0)+IF((S37*W36)>=150000,(S37*W36)-150000,0)+IF((T37*W36)>=150000,(T37*W36)-150000,0)+IF((U37*W36)>=150000,(U37*W36)-150000,0) -> 120000 | AA37: =ROUNDDOWN(AA36*10%,-1) -> 320 | AB37: =IF(V36<8,0,(TRUNC(X36*3.545%,-1))) -> 0 | AC37: =TRUNC(((AB37*12.95%)),-1) -> 0 | AH37: 2 | AI37: =AI36 -> 1
A38: =IF(B38>0,A36+1,"") -> 17 | B38: 백충현 | N38: 1 | O38: 1 | P38: 1 | Q38: 1 | V38: =SUM(F38:U39) -> 10 | W38: 180000 | X38: =V38*W38 -> 1800000 | Y38: =IF((F38*W38)>=150000,(F38*W38)-150000,0)+IF((G38*W38)>=150000,(G38*W38)-150000,0)+IF((H38*W38)>=150000,(H38*W38)-150000,0)+IF((I38*W38)>=150000,(I38*W38)-150000,0)+IF((J38*W38)>=150000,(J38*W38)-150000,0)+IF((K38*W38)>=150000,(K38*W38)-150000,0)+IF((L38*W38)>=150000,(L38*W38)-150000,0)+IF((M38*W38)>=150000,(M38*W38)-150000,0)+IF((N38*W38)>=150000,(N38*W38)-150000,0)+IF((O38*W38)>=150000,(O38*W38)-150000,0)+IF((P38*W38)>=150000,(P38*W38)-150000,0)+IF((Q38*W38)>=150000,(Q38*W38)-150000,0)+IF((R38*W38)>=150000,(R38*W38)-150000,0)+IF((S38*W38)>=150000,(S38*W38)-150000,0)+IF((T38*W38)>=150000,(T38*W38)-150000,0) -> 120000 | Z38: =+Y38+Y39 -> 300000 | AA38: =IF((ROUNDDOWN((+Z38*6%)*45%,-1))>=1000,(ROUNDDOWN((+Z38*6%)*45%,-1)),0) -> 8100 | AB38: =IFERROR(IF(DATEDIF(DATE(MID(C38,1,2),MID(C38,3,2),MID(C38,5,2)),$W$2,"y")>=60,0,IF(OR(V38>=8,X38>=2200000),TRUNC(X38*4.5%,-1),0)),0) -> 0 | AC38: =IFERROR(IF(AND((DATEDIF(TEXT(LEFT(C38,6),"00-00-00"),$W$2,"Y")>19),(DATEDIF(TEXT(LEFT(C38,6),"00-00-00"),$W$2,"Y")<65)),TRUNC(X38*0.9%,-1),0),0) -> 0 | AD38: =SUM(AA38:AC39) -> 80980 | AE38: =+X38-AD38 -> 1719020 | AG38: =IF(ISERROR(DATEDIF((DATEVALUE(LEFT(C38,2)&"-"&MID(C38,3,2)&"-"&MID(C38,5,2))),$W$2,"y")),"",DATEDIF((DATEVALUE(LEFT(C38,2)&"-"&MID(C38,3,2)&"-"&MID(C38,5,2))),$W$2,"y")) | AH38: 1 | AI38: =AI37 -> 1
H39: 1 | I39: 1 | J39: 1 | M39: 1 | N39: 1 | O39: 1 | Y39: =IF((F39*W38)>=150000,(F39*W38)-150000,0)+IF((G39*W38)>=150000,(G39*W38)-150000,0)+IF((H39*W38)>=150000,(H39*W38)-150000,0)+IF((I39*W38)>=150000,(I39*W38)-150000,0)+IF((J39*W38)>=150000,(J39*W38)-150000,0)+IF((K39*W38)>=150000,(K39*W38)-150000,0)+IF((L39*W38)>=150000,(L39*W38)-150000,0)+IF((M39*W38)>=150000,(M39*W38)-150000,0)+IF((N39*W38)>=150000,(N39*W38)-150000,0)+IF((O39*W38)>=150000,(O39*W38)-150000,0)+IF((P39*W38)>=150000,(P39*W38)-150000,0)+IF((Q39*W38)>=150000,(Q39*W38)-150000,0)+IF((R39*W38)>=150000,(R39*W38)-150000,0)+IF((S39*W38)>=150000,(S39*W38)-150000,0)+IF((T39*W38)>=150000,(T39*W38)-150000,0)+IF((U39*W38)>=150000,(U39*W38)-150000,0) -> 180000 | AA39: =ROUNDDOWN(AA38*10%,-1) -> 810 | AB39: =IF(V38<8,0,(TRUNC(X38*3.545%,-1))) -> 63810 | AC39: =TRUNC(((AB39*12.95%)),-1) -> 8260 | AH39: 2 | AI39: =AI38 -> 1
A40: =IF(B40>0,A38+1,"") -> 18 | B40: 이금수 | H40: 1 | I40: 1 | J40: 1 | N40: 1 | O40: 1 | P40: 1 | Q40: 1 | R40: 1 | S40: 1 | V40: =SUM(F40:U41) -> 20 | W40: 180000 | X40: =V40*W40 -> 3600000 | Y40: =IF((F40*W40)>=150000,(F40*W40)-150000,0)+IF((G40*W40)>=150000,(G40*W40)-150000,0)+IF((H40*W40)>=150000,(H40*W40)-150000,0)+IF((I40*W40)>=150000,(I40*W40)-150000,0)+IF((J40*W40)>=150000,(J40*W40)-150000,0)+IF((K40*W40)>=150000,(K40*W40)-150000,0)+IF((L40*W40)>=150000,(L40*W40)-150000,0)+IF((M40*W40)>=150000,(M40*W40)-150000,0)+IF((N40*W40)>=150000,(N40*W40)-150000,0)+IF((O40*W40)>=150000,(O40*W40)-150000,0)+IF((P40*W40)>=150000,(P40*W40)-150000,0)+IF((Q40*W40)>=150000,(Q40*W40)-150000,0)+IF((R40*W40)>=150000,(R40*W40)-150000,0)+IF((S40*W40)>=150000,(S40*W40)-150000,0)+IF((T40*W40)>=150000,(T40*W40)-150000,0) -> 270000 | Z40: =+Y40+Y41 -> 600000 | AA40: =IF((ROUNDDOWN((+Z40*6%)*45%,-1))>=1000,(ROUNDDOWN((+Z40*6%)*45%,-1)),0) -> 16200 | AB40: =IFERROR(IF(DATEDIF(DATE(MID(C40,1,2),MID(C40,3,2),MID(C40,5,2)),$W$2,"y")>=60,0,IF(OR(V40>=8,X40>=2200000),TRUNC(X40*4.5%,-1),0)),0) -> 0 | AC40: =IFERROR(IF(AND((DATEDIF(TEXT(LEFT(C40,6),"00-00-00"),$W$2,"Y")>19),(DATEDIF(TEXT(LEFT(C40,6),"00-00-00"),$W$2,"Y")<65)),TRUNC(X40*0.9%,-1),0),0) -> 0 | AD40: =SUM(AA40:AC41) -> 161960 | AE40: =+X40-AD40 -> 3438040 | AG40: =IF(ISERROR(DATEDIF((DATEVALUE(LEFT(C40,2)&"-"&MID(C40,3,2)&"-"&MID(C40,5,2))),$W$2,"y")),"",DATEDIF((DATEVALUE(LEFT(C40,2)&"-"&MID(C40,3,2)&"-"&MID(C40,5,2))),$W$2,"y")) | AH40: 1 | AI40: =AI39 -> 1
...

Sheet 증빙_철거
B1: 근로자 신분증 및 통장 사본 | T1: 1
T2: 1 | V2: 성명 | W2: 금액 | X2: 연락처 | Y2: 은행 | Z2: 계좌번호
B3: 공사명 : 24-25년 노후공임 리모델링공사 8권역(경남)_직영(일반철거) | O3: 동영종합건설㈜ | T3: 1 | V3: B | W3: AE | X3: AJ | Y3: AK | Z3: AL
A4: 신분증 | I4: 통장사본 | R4: 1 | S4: 1 | T4: =IF(명세서_철거!$AE$6=0,0,1) -> 1 | U4: =U13 -> 6 | W4: =W$3&$U4 -> AE6
R5: 2 | T5: =T4 -> 1
R6: 3 | T6: =T5 -> 1
R7: 4 | T7: =T6 -> 1
R8: 5 | T8: =T7 -> 1 | AA8: ☜ 신분증 및 통장사본 사진 필수 입력
R9: 6 | T9: =T8 -> 1
R10: 7 | T10: =T9 -> 1
R11: 8 | T11: =T10 -> 1
R12: 9 | T12: =T11 -> 1
A13: 성 명 | C13: =명세서_철거!$B$6 -> 김경숙 | E13: 연락처 | F13: =명세서_철거!$AJ$6 -> 010-2040-6604 | I13: 은행 | K13: =명세서_철거!$AK$6 -> 새마을금고 | L13: 계좌번호 | M13: =명세서_철거!$AL$6 -> 9002-1703-0114-6 | R13: 10 | T13: =T4 -> 1 | U13: 6 | V13: =V$3&$U13 -> B6 | X13: =X$3&$U13 -> AJ6 | Y13: =Y$3&$U13 -> AK6 | Z13: =Z$3&$U13 -> AL6 | AA13: ☜ 지급명세서 우측에 관련 정보 입력하면 여기서는 건드리지 않아도 됨.
A14: 신분증 | I14: 통장사본 | R14: 1 | T14: =T4 -> 1
R15: 2 | T15: =T14 -> 1
R16: 3 | T16: =T15 -> 1
R17: 4 | T17: =T16 -> 1
R18: 5 | T18: =T17 -> 1
R19: 6 | T19: =T18 -> 1
R20: 7 | T20: =T19 -> 1
R21: 8 | T21: =T20 -> 1
R22: 9 | T22: =T21 -> 1
A23: =$A$13 -> 성 명 | C23: =명세서_철거!$B$8 -> 김숙자 | E23: =$E$13 -> 연락처 | F23: =명세서_철거!$AJ$8 -> 0 | I23: =$I$13 -> 은행 | K23: =명세서_철거!$AK$8 -> 0 | L23: =$L$13 -> 계좌번호 | M23: =명세서_철거!$AL$8 -> 0 | R23: 10 | T23: =T4 -> 1 | U23: =U13+2 -> 8 | V23: =V$3&$U23 -> B8 | X23: =X$3&$U23 -> AJ8 | Y23: =Y$3&$U23 -> AK8 | Z23: =Z$3&$U23 -> AL8
A24: 신분증 | I24: 통장사본 | R24: 1 | T24: =T4 -> 1
R25: 2 | T25: =T24 -> 1
R26: 3 | T26: =T25 -> 1
R27: 4 | T27: =T26 -> 1
R28: 5 | T28: =T27 -> 1
R29: 6 | T29: =T28 -> 1
R30: 7 | T30: =T29 -> 1
R31: 8 | T31: =T30 -> 1
R32: 9 | T32: =T31 -> 1
A33: =$A$13 -> 성 명 | C33: =명세서_철거!$B$10 -> 김진영 | E33: =$E$13 -> 연락처 | F33: =명세서_철거!$AJ$10 -> 0 | I33: =$I$13 -> 은행 | K33: =명세서_철거!$AK$10 -> 0 | L33: =$L$13 -> 계좌번호 | M33: =명세서_철거!$AL$10 -> 0 | R33: 10 | T33: =T32 -> 1 | U33: =U23+2 -> 10 | V33: =V$3&$U33 -> B10 | X33: =X$3&$U33 -> AJ10 | Y33: =Y$3&$U33 -> AK10 | Z33: =Z$3&$U33 -> AL10
A34: 신분증 | I34: 통장사본 | R34: 1 | S34: =S4+1 -> 2 | T34: =IF(명세서_철거!$AE$12=0,0,1) -> 1 | U34: =U43 -> 12 | W34: =W$3&$U34 -> AE12
R35: 2 | T35: =T34 -> 1
R36: 3 | T36: =T35 -> 1
R37: 4 | T37: =T36 -> 1
R38: 5 | T38: =T37 -> 1
R39: 6 | T39: =T38 -> 1
R40: 7 | T40: =T39 -> 1
...
